Workbook
Name L_Scenarios: Scenario!$D$10:$D$12
Name Million: Input!$G$15
Name Scenarioused: Scenario!$D$9

Sheet Cover
C7: Nudu Noodles
C8: Financial Model for F2022F to F2026F
C10: Modeller: | D10: Animashaun jafar
C11: Version: | D11: Ver 1.01
C12: Base year | D12: 2021
C14: Circularity: | D14: Net interest expense line of the P&L

Sheet Historical FS
C2: Nudu Noodles
C3: Income Statement
C5: [$'millions]
G7: 2019 | H7: =G7+1 -> 2020 | I7: =H7+1 -> 2021
C9: Revenue growth | E9: [%] | H9: =H13/G13-1 -> -0.0086538462 | I9: =I13/H13-1 -> 0.032007759
C10: COGS [% of revenue] | E10: [%] | G10: =G15/G13 -> 0.31563462 | H10: =H15/H13 -> 0.35790495 | I10: =I15/I13 -> 0.37007519
C11: SG&A [% of revenue] | E11: [%] | G11: =G16/G13 -> 0.19976923 | H11: =H16/H13 -> 0.21132881 | I11: =I16/I13 -> 0.21537594
D13: Revenue | E13: [$'m] | G13: 520 | H13: 515.5 | I13: 532
D15: Cost of sales | E15: [$'m] | G15: 164.13 | H15: 184.5 | I15: 196.88
D16: SG&A | E16: [$'m] | G16: 103.88 | H16: 108.94 | I16: 114.58
D17: Total costs | E17: [$'m] | G17: =SUM(G15:G16) -> 268.01 | H17: =SUM(H15:H16) -> 293.44 | I17: =SUM(I15:I16) -> 311.46
D19: Cost adjustments -Gain/(loss) | E19: [$'m] | G19: -7 | H19: -4.2 | I19: 30
D20: EBITDA | E20: [$'m] | G20: =G13-G17+G19 -> 244.99 | H20: =H13-H17+H19 -> 217.86 | I20: =I13-I17+I19 -> 250.54
D22: Depreciation | E22: [$'m] | G22: 5.1 | H22: 5.5733333 | I22: 5.88
D23: EBIT | E23: [$'m] | G23: =G20-G22 -> 239.89 | H23: =H20-H22 -> 212.28667 | I23: =I20-I22 -> 244.66
D25: Cost adjustments -Gain/(loss) | E25: [$'m] | G25: -58 | H25: -61.95 | I25: -52.9
D26: Net Interest Expense | E26: [$'m] | G26: 62 | H26: 56.6 | I26: 59.1
D27: EBT | E27: [$'m] | G27: =G23+G25-G26 -> 119.89 | H27: =H23+H25-H26 -> 93.736667 | I27: =I23+I25-I26 -> 132.66
D29: Current Taxes | E29: [$'m] | G29: 40.5 | H29: 22.7 | I29: 24.8
D30: Deferred Income Taxes | E30: [$'m] | G30: 16.9 | H30: 31.7 | I30: 24
D31: Total Income Taxes | E31: [$'m] | G31: =SUM(G29:G30) -> 57.4 | H31: =SUM(H29:H30) -> 54.4 | I31: =SUM(I29:I30) -> 48.8
D33: Net Income | E33: [$'m] | G33: =G27-G31 -> 62.49 | H33: =H27-H31 -> 39.336667 | I33: =I27-I31 -> 83.86
D35: Preferred dividend | E35: [$'m] | G35: 0.5 | H35: 0.5 | I35: 0.5
D36: Net Income to Common | E36: [$'m] | G36: =G33-G35 -> 61.99 | H36: =H33-H35 -> 38.836667 | I36: =I33-I35 -> 83.36
C39: Nudu Noodles
C40: Cash Flow Statement
C42: [$'millions]
G43: 2019 | H43: =G43+1 -> 2020 | I43: =H43+1 -> 2021
C44: Operating Activities
D45: Net Income | E45: [$'m] | G45: =G33 -> 62.49 | H45: =H33 -> 39.336667 | I45: =I33 -> 83.86
D46: Depreciation | E46: [$'m] | G46: 5.1 | H46: 5.5733333 | I46: 5.88
D47: Deferred Income Taxes | E47: [$'m] | G47: 1.1266667 | H47: 2.1133333 | I47: 1.6
D48: Changes in Working Capital | E48: [$'m] | G48: -7.9333333 | H48: -0.3 | I48: -5.5866667
D49: Other | E49: [$'m] | G49: 10.793333 | H49: 10.946667 | I49: 16.14
D50: Operating Cash Flow | E50: [$'m] | G50: =SUM(G45:G49) -> 71.576667 | H50: =SUM(H45:H49) -> 57.67 | I50: =SUM(I45:I49) -> 101.89333
C52: Investing Activities
D53: CAPEX | E53: [$'m] | G53: -5.0266667 | H53: -5.38 | I53: -5.5
D54: Asset Dispositions | E54: [$'m] | G54: 0.13333333 | H54: 0.22666667 | I54: 0.7
D55: Other | E55: [$'m] | G55: -0.38666667 | H55: -0.28 | I55: -0.32
D56: Investing Cash Flow | E56: [$'m] | G56: =SUM(G53:G55) -> -5.28 | H56: =SUM(H53:H55) -> -5.4333333 | I56: =SUM(I53:I55) -> -5.12
...

Sheet Summary
B2: =Cover!$C$7 -> Nudu Noodles | I2: ="Financial Forecast "&$L$6&" to "&$P$6 -> Financial Forecast 2022 to 2026
B3: Summary | I3: ="BS Check: "&IF(Model!F115=0,"OK","ERROR") -> BS Check: OK | K3: =Scenarioused -> Scenario: Base Case
I5: Actual | J5: Actual | K5: Actual | L5: Forecast | M5: Forecast | N5: Forecast | O5: Forecast | P5: Forecast
F6: Units | G6: Inputs | I6: =J6-1 -> 2019 | J6: =K6-1 -> 2020 | K6: =Cover!$D$12 -> 2021 | L6: =K6+1 -> 2022 | M6: =L6+1 -> 2023 | N6: =M6+1 -> 2024 | O6: =N6+1 -> 2025 | P6: =O6+1 -> 2026
B8: Analysis based on: Base Case
C10: Revenue
D11: Total Revenue | F11: [$'m] | I11: 520 | J11: 515.5 | K11: 532 | L11: 559.49113 | M11: 652.44489 | N11: 678.17707 | O11: 682.19361 | P11: 734.28792
D12: Growth rate | F12: [%] | J12: -0.0086538462 | K12: 0.032007759 | L12: 0.051675047 | M12: 0.16613983 | N12: 0.039439638 | O12: 0.0059225456 | P12: 0.076362939
C13: Ebitda
D14: Ebitda | F14: [$'m] | I14: 244.99 | J14: 217.86 | K14: 250.54 | L14: 228.52209 | M14: 309.89194 | N14: 325.34754 | O14: 318.07353 | P14: 357.42363
D15: Growth rate | F15: [%] | J15: -0.11073921 | K15: 0.15000459 | L15: -0.087881809 | M15: 0.35606992 | N15: 0.049874164 | O15: -0.022357663 | P15: 0.12371387
D16: ebitda margin | F16: [%] | I16: 0.47113462 | J16: 0.42261882 | K16: 0.47093985 | L16: 0.40844632 | M16: 0.47497029 | N16: 0.47973833 | O16: 0.46625111 | P16: 0.48676224
C17: Net Profit
D18: Net Profit | F18: [$'m] | I18: 62.49 | J18: 39.336667 | K18: 83.86 | L18: 142.52623 | M18: 181.68443 | N18: 174.59943 | O18: 148.73021 | P18: 160.24539
D19: Growth rate | F19: %age | J19: -0.37051262 | K19: 1.1318532 | L19: 0.69957341 | M19: 0.27474386 | N19: -0.038996178 | O19: -0.14816328 | P19: 0.077423256
D20: Net Profit margin | F20: %age | I20: 0.12017308 | J20: 0.076307792 | K20: 0.15763158 | L20: 0.2547426 | M20: 0.27846709 | N20: 0.25745405 | O20: 0.21801759 | P20: 0.21823236
C21: Dupont Analysis
D22: ROE | F22: [%] | I22: 0.59440457 | J22: 0.29074072 | K22: 0.36368733 | L22: 0.39326709 | M22: 0.30884325 | N22: 0.25347678 | O22: 0.18709128 | P22: 0.16696759
D23: Net Profit margin | F23: [%] | I23: 0.12017308 | J23: 0.076307792 | K23: 0.15763158 | L23: 0.2547426 | M23: 0.27846709 | N23: 0.25745405 | O23: 0.21801759 | P23: 0.21823236
D24: Asset turnover | F24: multiples | I24: 2.2527035 | J24: 1.8727311 | K24: 1.4898232 | L24: 1.251074 | M24: 0.82083258 | N24: 0.74364546 | O24: 0.4917252 | P24: 0.55503116
D25: Financial Leverage | F25: multiples | I25: 2.1956895 | J25: 2.0345181 | K25: 1.5486391 | L25: 1.2339655 | M25: 1.3511689 | N25: 1.3239529 | O25: 1.7451773 | P25: 1.3784648
B27: Analysis based on: Best Case
C29: Revenue
D30: Total Revenue | F30: [$'m] | I30: 520 | J30: 515.5 | K30: 532 | L30: 564.59708 | M30: 664.80465 | N30: 699.81243 | O30: 699.58413 | P30: 755.91089
D31: Growth rate | F31: [%] | J31: -0.0086538462 | K31: 0.032007759 | L31: 0.061272697 | M31: 0.17748511 | N31: 0.052658744 | O31: -0.00032622997 | P31: 0.080514638
C32: Ebitda
D33: Ebitda | F33: [$'m] | I33: 244.99 | J33: 217.86 | K33: 250.54 | L33: 232.72043 | M33: 324.63108 | N33: 352.83539 | O33: 344.97359 | P33: 392.43509
D34: Growth rate | F34: [%] | J34: -0.11073921 | K34: 0.15000459 | L34: -0.071124671 | M34: 0.39494023 | N34: 0.086881103 | O34: -0.022281763 | P34: 0.13758009
D35: ebitda margin | F35: [%] | I35: 0.47113462 | J35: 0.42261882 | K35: 0.47093985 | L35: 0.41218851 | M35: 0.48831049 | N35: 0.50418566 | O35: 0.49311238 | P35: 0.51915523
C36: Net Profit
D37: Net Profit | F37: [$'m] | I37: 62.49 | J37: 39.336667 | K37: 83.86 | L37: 145.24995 | M37: 191.2338 | N37: 192.72512 | O37: 166.97717 | P37: 184.19874
D38: Growth rate | F38: %age | J38: -0.37051262 | K38: 1.1318532 | L38: 0.73205278 | M38: 0.3165843 | N38: 0.0077984407 | O38: -0.13359938 | P38: 0.10313732
D39: Net Profit margin | F39: %age | I39: 0.12017308 | J39: 0.076307792 | K39: 0.15763158 | L39: 0.25726302 | M39: 0.28765412 | N39: 0.2753954 | O39: 0.23868061 | P39: 0.24367786
C40: Dupont Analysis
D41: ROE | F41: [%] | I41: 0.59440457 | J41: 0.29074072 | K41: 0.36368733 | L41: 0.39853615 | M41: 0.32006795 | N41: 0.27082691 | O41: 0.20082768 | P41: 0.18162173
D42: Net Profit margin | F42: [%] | I42: 0.12017308 | J42: 0.076307792 | K42: 0.15763158 | L42: 0.25726302 | M42: 0.28765412 | N42: 0.2753954 | O42: 0.23868061 | P42: 0.24367786
D43: Asset turnover | F43: multiples | I43: 2.2527035 | J43: 1.8727311 | K43: 1.4898232 | L43: 1.2561931 | M43: 0.82706064 | N43: 0.76611024 | O43: 0.50400228 | P43: 0.57107041
D44: Financial Leverage | F44: multiples | I44: 2.1956895 | J44: 2.0345181 | K44: 1.5486391 | L44: 1.2332013 | M44: 1.3453468 | N44: 1.2836418 | O44: 1.669452 | P44: 1.305155
B46: Analysis based on: Worst Case
C48: Revenue
...

Sheet Input
B2: =Cover!$C$7 -> Nudu Noodles | I2: ="Financial Forecast "&$L$6&" to "&$P$6 -> Financial Forecast 2022 to 2026
B3: Input | I3: ="BS Check: "&IF(Model!F115=0,"OK","ERROR") -> BS Check: OK | K3: =Scenarioused -> Scenario: Base Case
I5: Actual | J5: Actual | K5: Actual | L5: Forecast | M5: Forecast | N5: Forecast | O5: Forecast | P5: Forecast
F6: Units | G6: Inputs | I6: =J6-1 -> 2019 | J6: =K6-1 -> 2020 | K6: =Cover!$D$12 -> 2021 | L6: =K6+1 -> 2022 | M6: =L6+1 -> 2023 | N6: =M6+1 -> 2024 | O6: =N6+1 -> 2025 | P6: =O6+1 -> 2026
B8: General Assumptions
D10: Days in the period | I10: =DATE(I6,12,31)-DATE(I6,1,1)+1 -> 365 | J10: =DATE(J6,12,31)-DATE(J6,1,1)+1 -> 366 | K10: =DATE(K6,12,31)-DATE(K6,1,1)+1 -> 365 | L10: =DATE(L6,12,31)-DATE(L6,1,1)+1 -> 365 | M10: =DATE(M6,12,31)-DATE(M6,1,1)+1 -> 365 | N10: =DATE(N6,12,31)-DATE(N6,1,1)+1 -> 366 | O10: =DATE(O6,12,31)-DATE(O6,1,1)+1 -> 365 | P10: =DATE(P6,12,31)-DATE(P6,1,1)+1 -> 365
C12: Style Guide
D13: Number | G13: 1234
D15: Millions | G15: 1000000
D16: Inputs | G16: 12345
D17: Percent | G17: 0.055
D18: Multiple | G18: 12
D19: Linked cells | G19: 12345
D20: Units | G20: [$'m]
D21: Total | G21: Text
D22: Headings 2 | G22: Text
B25: Revenue Assumptions
C27: Product-70g
D28: Production Capacity | F28: [units] | L28: 35000000 | M28: 35000000 | N28: 35000000 | O28: 33000000 | P28: 35000000
D29: Price | K29: 15
D30: Pricing growth | F30: [%] | L30: =Scenario!L16 -> 0.025 | M30: =Scenario!M16 -> 0.022 | N30: =Scenario!N16 -> 0.02 | O30: =Scenario!O16 -> 0.013 | P30: =Scenario!P16 -> 0.025
D31: Volume growth | F31: [%] | L31: =Scenario!L22 -> 0.03 | M31: =Scenario!M22 -> 0.035 | N31: =Scenario!N22 -> 0.02 | O31: =Scenario!O22 -> 0.025 | P31: =Scenario!P22 -> 0.03
C33: Product-100g
D34: =D28 -> Production Capacity | F34: [units] | M34: 4600000 | N34: 4600000 | O34: 4000000 | P34: 3800000
D35: Price | F35: [$/unit] | M35: 18
D36: Pricing growth | F36: [%] | N36: =Scenario!N29 -> 0.028 | O36: =Scenario!O29 -> 0.013 | P36: =Scenario!P29 -> 0.02
D37: Volume | F37: [units] | M37: 3500000
D38: Volume growth | F38: [%] | N38: =Scenario!N34 -> 0.02 | O38: =Scenario!O34 -> 0.025 | P38: =Scenario!P34 -> 0.03
C40: Auxillary Revenue
D41: Auxillary Sales | F41: [$'m] | K41: 70.5
D42: Auxillary Sales growth | F42: [%] | L42: =Scenario!L40 -> 0.025 | M42: =Scenario!M40 -> 0.025 | N42: =Scenario!N40 -> 0.025 | O42: =Scenario!O40 -> 0.025 | P42: =Scenario!P40 -> 0.025
B44: Production Cost Assumptions
C46: Variable Costs
D47: Wheat | F47: $/unit | L47: 2.8
D48: Potatoes Starch | F48: $/unit | L48: 1.2
D49: Other raw materials | F49: $/unit | L49: 1.9
D50: Total Variable Cost per unit | F50: $/unit | L50: =SUM(L47:L49) -> 5.9
C52: Aggregate Fixed Cost
D53: Capital Charges | F53: [$'m] | L53: 10.5
D54: Labour | F54: [$'m] | L54: 3.2
...

Sheet Scenario
B2: =Cover!$C$7 -> Nudu Noodles | I2: ="Financial Forecast "&$L$6&" to "&$P$6 -> Financial Forecast 2022 to 2026
B3: Scenario | I3: ="BS Check: "&IF(Model!F115=0,"OK","ERROR") -> BS Check: OK | K3: =Scenarioused -> Scenario: Base Case
I5: Actual | J5: Actual | K5: Actual | L5: Forecast | M5: Forecast | N5: Forecast | O5: Forecast | P5: Forecast
F6: Units | G6: Inputs | I6: =J6-1 -> 2019 | J6: =K6-1 -> 2020 | K6: =Cover!$D$12 -> 2021 | L6: =K6+1 -> 2022 | M6: =L6+1 -> 2023 | N6: =M6+1 -> 2024 | O6: =N6+1 -> 2025 | P6: =O6+1 -> 2026
B8: Scenario List
D9: ="Scenario: "&CHOOSE($E$9,D10,D11,D12) -> Scenario: Base Case | E9: 1
D10: Base Case
D11: Best Case
D12: Worst Case
B15: Pricing growth-70g
C16: Used in the model | F16: [%] | L16: =CHOOSE($E$9,L17,L18,L19) -> 0.025 | M16: =CHOOSE($E$9,M17,M18,M19) -> 0.022 | N16: =CHOOSE($E$9,N17,N18,N19) -> 0.02 | O16: =CHOOSE($E$9,O17,O18,O19) -> 0.013 | P16: =CHOOSE($E$9,P17,P18,P19) -> 0.025
D17: Base Case | F17: [%] | L17: 0.025 | M17: 0.022 | N17: 0.02 | O17: 0.013 | P17: 0.025
D18: Best Case | F18: [%] | L18: 0.03 | M18: 0.03 | N18: 0.03 | O18: 0.018 | P18: 0.03
D19: Worst Case | F19: [%] | L19: 0.02 | M19: 0.02 | N19: 0.02 | O19: 0.008 | P19: 0.02
B21: Volume growth-70g
C22: Used in the model | F22: [%] | L22: =CHOOSE($E$9,L23,L24,L25) -> 0.03 | M22: =CHOOSE($E$9,M23,M24,M25) -> 0.035 | N22: =CHOOSE($E$9,N23,N24,N25) -> 0.02 | O22: =CHOOSE($E$9,O23,O24,O25) -> 0.025 | P22: =CHOOSE($E$9,P23,P24,P25) -> 0.03
D23: Base Case | F23: [%] | L23: 0.03 | M23: 0.035 | N23: 0.02 | O23: 0.025 | P23: 0.03
D24: Best Case | F24: [%] | L24: 0.035 | M24: 0.04 | N24: 0.025 | O24: 0.03 | P24: 0.035
D25: Worst Case | F25: [%] | L25: 0.025 | M25: 0.03 | N25: 0.015 | O25: 0.02 | P25: 0.025
B27: Pricing growth-100g
C28: Used in the model | F28: [%] | L28: =CHOOSE($E$9,L29,L30,L31) -> 0 | M28: =CHOOSE($E$9,M29,M30,M31) -> 0 | N28: =CHOOSE($E$9,N29,N30,N31) -> 0.028 | O28: =CHOOSE($E$9,O29,O30,O31) -> 0.013 | P28: =CHOOSE($E$9,P29,P30,P31) -> 0.02
D29: Base Case | F29: [%] | N29: 0.028 | O29: 0.013 | P29: 0.02
D30: Best Case | F30: [%] | N30: 0.033 | O30: 0.018 | P30: 0.025
D31: Worst Case | F31: [%] | N31: 0.023 | O31: 0.008 | P31: 0.015
B33: Volume growth-100g
C34: Used in the model | F34: [%] | L34: =CHOOSE($E$9,L35,L36,L37) -> 0 | M34: =CHOOSE($E$9,M35,M36,M37) -> 0 | N34: =CHOOSE($E$9,N35,N36,N37) -> 0.02 | O34: =CHOOSE($E$9,O35,O36,O37) -> 0.025 | P34: =CHOOSE($E$9,P35,P36,P37) -> 0.03
D35: Base Case | F35: [%] | L35: 0 | M35: 0 | N35: 0.02 | O35: 0.025 | P35: 0.03
D36: Best Case | F36: [%] | L36: 0 | M36: 0 | N36: 0.025 | O36: 0.035 | P36: 0.04
D37: Worst Case | F37: [%] | L37: 0 | M37: 0 | N37: 0.015 | O37: 0.015 | P37: 0.015
B39: Auxillary Sales growth
C40: Used in the model | F40: [%] | L40: =CHOOSE($E$9,L41,L42,L43) -> 0.025 | M40: =CHOOSE($E$9,M41,M42,M43) -> 0.025 | N40: =CHOOSE($E$9,N41,N42,N43) -> 0.025 | O40: =CHOOSE($E$9,O41,O42,O43) -> 0.025 | P40: =CHOOSE($E$9,P41,P42,P43) -> 0.025
D41: Base Case | F41: [%] | L41: 0.025 | M41: 0.025 | N41: 0.025 | O41: 0.025 | P41: 0.025
D42: Best Case | F42: [%] | L42: 0.03 | M42: 0.03 | N42: 0.03 | O42: 0.03 | P42: 0.03
D43: Worst Case | F43: [%] | L43: 0.02 | M43: 0.02 | N43: 0.02 | O43: 0.02 | P43: 0.02
B45: Cost Inflation
C46: Used in the model | F46: [%] | L46: =CHOOSE($E$9,L47,L48,L49) -> 0.02 | M46: =CHOOSE($E$9,M47,M48,M49) -> 0.035 | N46: =CHOOSE($E$9,N47,N48,N49) -> 0.03 | O46: =CHOOSE($E$9,O47,O48,O49) -> 0.032 | P46: =CHOOSE($E$9,P47,P48,P49) -> 0.035
D47: Base Case | F47: [%] | L47: 0.02 | M47: 0.035 | N47: 0.03 | O47: 0.032 | P47: 0.035
D48: Best Case | F48: [%] | L48: 0.01 | M48: 0.025 | N48: 0.02 | O48: 0.022 | P48: 0.025
D49: Worst Case | F49: [%] | L49: 0.035 | M49: 0.05 | N49: 0.045 | O49: 0.047 | P49: 0.05

Sheet Model
B2: =Cover!$C$7 -> Nudu Noodles | I2: ="Financial Forecast "&$L$6&" to "&$P$6 -> Financial Forecast 2022 to 2026
B3: Model | I3: ="BS Check: "&IF(Model!F115=0,"OK","ERROR") -> BS Check: OK | K3: =Scenarioused -> Scenario: Base Case
I5: Actual | J5: Actual | K5: Actual | L5: Forecast | M5: Forecast | N5: Forecast | O5: Forecast | P5: Forecast
F6: Units | G6: Inputs | I6: =J6-1 -> 2019 | J6: =K6-1 -> 2020 | K6: =Cover!$D$12 -> 2021 | L6: =K6+1 -> 2022 | M6: =L6+1 -> 2023 | N6: =M6+1 -> 2024 | O6: =N6+1 -> 2025 | P6: =O6+1 -> 2026
A8: Financial Statements
B10: Income Statement
D12: ='Historical FS'!D13 -> Revenue | F12: ='Historical FS'!E13 -> [$'m] | I12: ='Historical FS'!G13 -> 520 | J12: ='Historical FS'!H13 -> 515.5 | K12: ='Historical FS'!I13 -> 532 | L12: =L157 -> 559.49113 | M12: =M157 -> 652.44489 | N12: =N157 -> 678.17707 | O12: =O157 -> 682.19361 | P12: =P157 -> 734.28792
D14: ='Historical FS'!D15 -> Cost of sales | I14: ='Historical FS'!G15 -> 164.13 | J14: ='Historical FS'!H15 -> 184.5 | K14: ='Historical FS'!I15 -> 196.88 | L14: =L191 -> 205.76903 | M14: =M191 -> 212.97095 | N14: =N191 -> 219.36008 | O14: =O191 -> 226.3796 | P14: =P191 -> 234.30289
D15: ='Historical FS'!D16 -> SG&A | F15: ='Historical FS'!E16 -> [$'m] | I15: ='Historical FS'!G16 -> 103.88 | J15: ='Historical FS'!H16 -> 108.94 | K15: ='Historical FS'!I16 -> 114.58 | L15: =L193 -> 125.2 | M15: =M193 -> 129.582 | N15: =N193 -> 133.46946 | O15: =O193 -> 137.74048 | P15: =P193 -> 142.5614
D16: ='Historical FS'!D17 -> Total costs | F16: ='Historical FS'!E17 -> [$'m] | I16: =SUM(I14:I15) -> 268.01 | J16: =SUM(J14:J15) -> 293.44 | K16: =SUM(K14:K15) -> 311.46 | L16: =SUM(L14:L15) -> 330.96903 | M16: =SUM(M14:M15) -> 342.55295 | N16: =SUM(N14:N15) -> 352.82954 | O16: =SUM(O14:O15) -> 364.12008 | P16: =SUM(P14:P15) -> 376.86429
D18: ='Historical FS'!D19 -> Cost adjustments -Gain/(loss) | F18: ='Historical FS'!E19 -> [$'m] | I18: ='Historical FS'!G19 -> -7 | J18: ='Historical FS'!H19 -> -4.2 | K18: ='Historical FS'!I19 -> 30 | L18: =Input!L133 -> 0 | M18: =Input!M133 -> 0 | N18: =Input!N133 -> 0 | O18: =Input!O133 -> 0 | P18: =Input!P133 -> 0
D19: ='Historical FS'!D20 -> EBITDA | F19: ='Historical FS'!E20 -> [$'m] | I19: =I12-I16+I18 -> 244.99 | J19: =J12-J16+J18 -> 217.86 | K19: =K12-K16+K18 -> 250.54 | L19: =L12-L16+L18 -> 228.52209 | M19: =M12-M16+M18 -> 309.89194 | N19: =N12-N16+N18 -> 325.34754 | O19: =O12-O16+O18 -> 318.07353 | P19: =P12-P16+P18 -> 357.42363
D21: ='Historical FS'!D22 -> Depreciation | F21: ='Historical FS'!E22 -> [$'m] | I21: ='Historical FS'!G22 -> 5.1 | J21: ='Historical FS'!H22 -> 5.5733333 | K21: ='Historical FS'!I22 -> 5.88 | L21: =L215 -> 6.0773333 | M21: =M215 -> 26.910667 | N21: =N215 -> 51.910667 | O21: =O215 -> 76.910667 | P21: =P215 -> 96.094
D22: ='Historical FS'!D23 -> EBIT | F22: ='Historical FS'!E23 -> [$'m] | I22: =I19-I21 -> 239.89 | J22: =J19-J21 -> 212.28667 | K22: =K19-K21 -> 244.66 | L22: =L19-L21 -> 222.44476 | M22: =M19-M21 -> 282.98127 | N22: =N19-N21 -> 273.43687 | O22: =O19-O21 -> 241.16286 | P22: =P19-P21 -> 261.32963
D24: ='Historical FS'!D25 -> Cost adjustments -Gain/(loss) | F24: ='Historical FS'!E25 -> [$'m] | I24: ='Historical FS'!G25 -> -58 | J24: ='Historical FS'!H25 -> -61.95 | K24: ='Historical FS'!I25 -> -52.9 | L24: =Input!L134 -> 0 | M24: =Input!M134 -> 0 | N24: =Input!N134 -> 0 | O24: =Input!O134 -> 0 | P24: =Input!P134 -> 0
D25: ='Historical FS'!D26 -> Net Interest Expense | F25: ='Historical FS'!E26 -> [$'m] | I25: ='Historical FS'!G26 -> 62 | J25: ='Historical FS'!H26 -> 56.6 | K25: ='Historical FS'!I26 -> 59.1 | L25: =L344 -> 3.8487203 | M25: =M344 -> 4.1385551 | N25: =N344 -> 4.8331392 | O25: =O344 -> 12.375578 | P25: =P344 -> 14.827289
D26: ='Historical FS'!D27 -> EBT | F26: ='Historical FS'!E27 -> [$'m] | I26: =I22+I24-I25 -> 119.89 | J26: =J22+J24-J25 -> 93.736667 | K26: =K22+K24-K25 -> 132.66 | L26: =L22+L24-L25 -> 218.59604 | M26: =M22+M24-M25 -> 278.84271 | N26: =N22+N24-N25 -> 268.60373 | O26: =O22+O24-O25 -> 228.78728 | P26: =P22+P24-P25 -> 246.50234
D28: ='Historical FS'!D29 -> Current Taxes | F28: ='Historical FS'!E29 -> [$'m] | I28: ='Historical FS'!G29 -> 40.5 | J28: ='Historical FS'!H29 -> 22.7 | K28: ='Historical FS'!I29 -> 24.8 | L28: =L227 -> 66.008613 | M28: =M227 -> 87.09495 | N28: =N227 -> 83.511306 | O28: =O227 -> 69.575549 | P28: =P227 -> 75.77582
D29: ='Historical FS'!D30 -> Deferred Income Taxes | F29: ='Historical FS'!E30 -> [$'m] | I29: ='Historical FS'!G30 -> 16.9 | J29: ='Historical FS'!H30 -> 31.7 | K29: ='Historical FS'!I30 -> 24 | L29: =L228 -> 10.5 | M29: =M228 -> 10.5 | N29: =N228 -> 10.5 | O29: =O228 -> 10.5 | P29: =P228 -> 10.5
D30: ='Historical FS'!D31 -> Total Income Taxes | F30: ='Historical FS'!E31 -> [$'m] | I30: =SUM(I28:I29) -> 57.4 | J30: =SUM(J28:J29) -> 54.4 | K30: =SUM(K28:K29) -> 48.8 | L30: =SUM(L28:L29) -> 76.508613 | M30: =SUM(M28:M29) -> 97.59495 | N30: =SUM(N28:N29) -> 94.011306 | O30: =SUM(O28:O29) -> 80.075549 | P30: =SUM(P28:P29) -> 86.27582
D32: ='Historical FS'!D33 -> Net Income | F32: ='Historical FS'!E33 -> [$'m] | I32: =I26-I30 -> 62.49 | J32: =J26-J30 -> 39.336667 | K32: =K26-K30 -> 83.86 | L32: =L26-L30 -> 142.08742 | M32: =M26-M30 -> 181.24776 | N32: =N26-N30 -> 174.59243 | O32: =O26-O30 -> 148.71173 | P32: =P26-P30 -> 160.22652
D34: ='Historical FS'!D35 -> Preferred dividend | F34: ='Historical FS'!E35 -> [$'m] | I34: ='Historical FS'!G35 -> 0.5 | J34: ='Historical FS'!H35 -> 0.5 | K34: ='Historical FS'!I35 -> 0.5 | L34: =L270 -> 0.082 | M34: =M270 -> 7.207 | N34: =N270 -> 7.207 | O34: =O270 -> 7.207 | P34: =P270 -> 7.207
D35: ='Historical FS'!D36 -> Net Income to Common | F35: ='Historical FS'!E36 -> [$'m] | I35: =I32-I34 -> 61.99 | J35: =J32-J34 -> 38.836667 | K35: =K32-K34 -> 83.36 | L35: =L32-L34 -> 142.00542 | M35: =M32-M34 -> 174.04076 | N35: =N32-N34 -> 167.38543 | O35: =O32-O34 -> 141.50473 | P35: =P32-P34 -> 153.01952
D37: EBITDA margin | F37: [%] | I37: =I19/I12 -> 0.47113462 | J37: =J19/J12 -> 0.42261882 | K37: =K19/K12 -> 0.47093985 | L37: =L19/L12 -> 0.40844632 | M37: =M19/M12 -> 0.47497029 | N37: =N19/N12 -> 0.47973833 | O37: =O19/O12 -> 0.46625111 | P37: =P19/P12 -> 0.48676224
D38: Dupont Analysis
D39: ROE | F39: [%] | I39: =I32/I111 -> 0.59440457 | J39: =J32/J111 -> 0.29074072 | K39: =K32/K111 -> 0.36368733 | L39: =L32/L111 -> 0.39241266 | M39: =M32/M111 -> 0.30844524 | N39: =N32/N111 -> 0.25371039 | O39: =O32/O111 -> 0.18722718 | P39: =P32/P111 -> 0.16706803
D40: Net Profit margin | F40: [%] | I40: =I32/I12 -> 0.12017308 | J40: =J32/J12 -> 0.076307792 | K40: =K32/K12 -> 0.15763158 | L40: =L32/L12 -> 0.25395832 | M40: =M32/M12 -> 0.27779782 | N40: =N32/N12 -> 0.25744371 | O40: =O32/O12 -> 0.21799051 | P40: =P32/P12 -> 0.21820667
D41: Asset turnover | F41: multiples | I41: =I12/I91 -> 2.2527035 | J41: =J12/J91 -> 1.8727311 | K41: =K12/K91 -> 1.4898232 | L41: =L12/L91 -> 1.1837085 | M41: =M12/M91 -> 0.8215112 | N41: =N12/N91 -> 0.74364546 | O41: =O12/O91 -> 0.4917252 | P41: =P12/P91 -> 0.55503116
D42: Financial Leverage | F42: multiples | I42: =I91/I111 -> 2.1956895 | J42: =J91/J111 -> 2.0345181 | K42: =K91/K111 -> 1.5486391 | L42: =L91/L111 -> 1.3053766 | M42: =M91/M111 -> 1.3515613 | N42: =N91/N111 -> 1.3252262 | O42: =O91/O111 -> 1.7466619 | P42: =P91/P111 -> 1.3794563
B45: Cash flow Statement
D47: ='Historical FS'!C44 -> Operating Activities
D48: ='Historical FS'!D45 -> Net Income | F48: [$'m] | I48: ='Historical FS'!G45 -> 62.49 | J48: ='Historical FS'!H45 -> 39.336667 | K48: ='Historical FS'!I45 -> 83.86 | L48: =L32 -> 142.08742 | M48: =M32 -> 181.24776 | N48: =N32 -> 174.59243 | O48: =O32 -> 148.71173 | P48: =P32 -> 160.22652
D49: ='Historical FS'!D46 -> Depreciation | F49: [$'m] | I49: ='Historical FS'!G46 -> 5.1 | J49: ='Historical FS'!H46 -> 5.5733333 | K49: ='Historical FS'!I46 -> 5.88 | L49: =L21 -> 6.0773333 | M49: =M21 -> 26.910667 | N49: =N21 -> 51.910667 | O49: =O21 -> 76.910667 | P49: =P21 -> 96.094
D50: ='Historical FS'!D47 -> Deferred Income Taxes | F50: [$'m] | I50: ='Historical FS'!G47 -> 1.1266667 | J50: ='Historical FS'!H47 -> 2.1133333 | K50: ='Historical FS'!I47 -> 1.6 | L50: =L29 -> 10.5 | M50: =M29 -> 10.5 | N50: =N29 -> 10.5 | O50: =O29 -> 10.5 | P50: =P29 -> 10.5
D51: ='Historical FS'!D48 -> Changes in Working Capital | F51: [$'m] | I51: ='Historical FS'!G48 -> -7.9333333 | J51: ='Historical FS'!H48 -> -0.3 | K51: ='Historical FS'!I48 -> -5.5866667 | L51: =L259 -> -1.3452151 | M51: =M259 -> -9.0454519 | N51: =N259 -> -1.8887439 | O51: =O259 -> -0.15609841 | P51: =P259 -> -4.616384
D52: ='Historical FS'!D49 -> Other | F52: [$'m] | I52: ='Historical FS'!G49 -> 10.793333 | J52: ='Historical FS'!H49 -> 10.946667 | K52: ='Historical FS'!I49 -> 16.14 | L52: =Input!L135 -> 0 | M52: =Input!M135 -> 0 | N52: =Input!N135 -> 0 | O52: =Input!O135 -> 0 | P52: =Input!P135 -> 0
D53: ='Historical FS'!D50 -> Operating Cash Flow | F53: [$'m] | I53: =SUM(I48:I52) -> 71.576667 | J53: =SUM(J48:J52) -> 57.67 | K53: =SUM(K48:K52) -> 101.89333 | L53: =SUM(L48:L52) -> 157.31954 | M53: =SUM(M48:M52) -> 209.61298 | N53: =SUM(N48:N52) -> 235.11435 | O53: =SUM(O48:O52) -> 235.9663 | P53: =SUM(P48:P52) -> 262.20414
D55: ='Historical FS'!C52 -> Investing Activities
D56: ='Historical FS'!D53 -> CAPEX | F56: [$'m] | I56: ='Historical FS'!G53 -> -5.0266667 | J56: ='Historical FS'!H53 -> -5.38 | K56: ='Historical FS'!I53 -> -5.5 | L56: =-Input!L64 -> -75 | M56: =-Input!M64 -> -550 | N56: =-Input!N64 -> -200 | O56: =-Input!O64 -> -550 | P56: =-Input!P64 -> -25.5
D57: ='Historical FS'!D54 -> Asset Dispositions | F57: [$'m] | I57: ='Historical FS'!G54 -> 0.13333333 | J57: ='Historical FS'!H54 -> 0.22666667 | K57: ='Historical FS'!I54 -> 0.7 | L57: =Input!L142 -> 0 | M57: =Input!M142 -> 0 | N57: =Input!N142 -> 0 | O57: =Input!O142 -> 0 | P57: =Input!P142 -> 0
...
